[2022-10-28T22:37:49.481+0000] {taskinstance.py:1165} INFO - Dependencies all met for <TaskInstance: carga_tb_carteira.criando_dataset manual__2022-10-28T22:28:57.533945+00:00 [queued]>
[2022-10-28T22:37:49.489+0000] {taskinstance.py:1165} INFO - Dependencies all met for <TaskInstance: carga_tb_carteira.criando_dataset manual__2022-10-28T22:28:57.533945+00:00 [queued]>
[2022-10-28T22:37:49.489+0000] {taskinstance.py:1362} INFO - 
--------------------------------------------------------------------------------
[2022-10-28T22:37:49.489+0000] {taskinstance.py:1363} INFO - Starting attempt 3 of 3
[2022-10-28T22:37:49.489+0000] {taskinstance.py:1364} INFO - 
--------------------------------------------------------------------------------
[2022-10-28T22:37:49.506+0000] {taskinstance.py:1383} INFO - Executing <Task(BigQueryCreateEmptyDatasetOperator): criando_dataset> on 2022-10-28 22:28:57.533945+00:00
[2022-10-28T22:37:49.512+0000] {standard_task_runner.py:55} INFO - Started process 17993 to run task
[2022-10-28T22:37:49.518+0000] {standard_task_runner.py:82} INFO - Running: ['airflow', 'tasks', 'run', 'carga_tb_carteira', 'criando_dataset', 'manual__2022-10-28T22:28:57.533945+00:00', '--job-id', '76', '--raw', '--subdir', 'DAGS_FOLDER/carga_tb_carteira.py', '--cfg-path', '/tmp/tmpo1f9q0mg']
[2022-10-28T22:37:49.521+0000] {standard_task_runner.py:83} INFO - Job 76: Subtask criando_dataset
[2022-10-28T22:37:49.579+0000] {task_command.py:376} INFO - Running <TaskInstance: carga_tb_carteira.criando_dataset manual__2022-10-28T22:28:57.533945+00:00 [running]> on host cs-1097450612417-default
[2022-10-28T22:37:49.639+0000] {taskinstance.py:1590} INFO - Exporting the following env vars:
AIRFLOW_CTX_DAG_EMAIL=airflow@example.com
AIRFLOW_CTX_DAG_OWNER=Marcelo Henrique
AIRFLOW_CTX_DAG_ID=carga_tb_carteira
AIRFLOW_CTX_TASK_ID=criando_dataset
AIRFLOW_CTX_EXECUTION_DATE=2022-10-28T22:28:57.533945+00:00
AIRFLOW_CTX_TRY_NUMBER=3
AIRFLOW_CTX_DAG_RUN_ID=manual__2022-10-28T22:28:57.533945+00:00
[2022-10-28T22:37:49.645+0000] {base.py:71} INFO - Using connection ID 'gcp_conn' for task execution.
[2022-10-28T22:37:49.646+0000] {bigquery.py:449} INFO - datasetId was not specified in `dataset_reference`. Will use default value carteira_acoes.
[2022-10-28T22:37:49.646+0000] {bigquery.py:449} INFO - projectId was not specified in `dataset_reference`. Will use default value US.
[2022-10-28T22:37:49.646+0000] {bigquery.py:460} INFO - Creating dataset: carteira_acoes in project: US 
[2022-10-28T22:37:49.712+0000] {taskinstance.py:1851} ERROR - Task failed with exception
Traceback (most recent call last):
  File "/home/marcelohenriqueleite35/carteira_ativos/env/lib/python3.9/site-packages/airflow/providers/google/cloud/operators/bigquery.py", line 1849, in execute
    dataset = bq_hook.create_empty_dataset(
  File "/home/marcelohenriqueleite35/carteira_ativos/env/lib/python3.9/site-packages/airflow/providers/google/common/hooks/base_google.py", line 464, in inner_wrapper
    return func(self, *args, **kwargs)
  File "/home/marcelohenriqueleite35/carteira_ativos/env/lib/python3.9/site-packages/airflow/providers/google/cloud/hooks/bigquery.py", line 461, in create_empty_dataset
    dataset_object = self.get_client(project_id=project_id, location=location).create_dataset(
  File "/home/marcelohenriqueleite35/carteira_ativos/env/lib/python3.9/site-packages/google/cloud/bigquery/client.py", line 632, in create_dataset
    api_response = self._call_api(
  File "/home/marcelohenriqueleite35/carteira_ativos/env/lib/python3.9/site-packages/google/cloud/bigquery/client.py", line 782, in _call_api
    return call()
  File "/home/marcelohenriqueleite35/carteira_ativos/env/lib/python3.9/site-packages/google/api_core/retry.py", line 283, in retry_wrapped_func
    return retry_target(
  File "/home/marcelohenriqueleite35/carteira_ativos/env/lib/python3.9/site-packages/google/api_core/retry.py", line 190, in retry_target
    return target()
  File "/home/marcelohenriqueleite35/carteira_ativos/env/lib/python3.9/site-packages/google/cloud/_http/__init__.py", line 494, in api_request
    raise exceptions.from_http_response(response)
google.api_core.exceptions.BadRequest: 400 POST https://bigquery.googleapis.com/bigquery/v2/projects/US/datasets?prettyPrint=false: Invalid resource name projects/US; Project id: US
[2022-10-28T22:37:49.719+0000] {taskinstance.py:1401} INFO - Marking task as FAILED. dag_id=carga_tb_carteira, task_id=criando_dataset, execution_date=20221028T222857, start_date=20221028T223749, end_date=20221028T223749
[2022-10-28T22:37:49.744+0000] {standard_task_runner.py:100} ERROR - Failed to execute job 76 for task criando_dataset (400 POST https://bigquery.googleapis.com/bigquery/v2/projects/US/datasets?prettyPrint=false: Invalid resource name projects/US; Project id: US; 17993)
[2022-10-28T22:37:49.769+0000] {local_task_job.py:164} INFO - Task exited with return code 1
[2022-10-28T22:37:49.799+0000] {local_task_job.py:273} INFO - 0 downstream tasks scheduled from follow-on schedule check
