[2022-10-28T01:45:36.055+0000] {taskinstance.py:1165} INFO - Dependencies all met for <TaskInstance: carga_tb_carteira.teste manual__2022-10-28T01:45:32.431312+00:00 [queued]>
[2022-10-28T01:45:36.068+0000] {taskinstance.py:1165} INFO - Dependencies all met for <TaskInstance: carga_tb_carteira.teste manual__2022-10-28T01:45:32.431312+00:00 [queued]>
[2022-10-28T01:45:36.069+0000] {taskinstance.py:1362} INFO - 
--------------------------------------------------------------------------------
[2022-10-28T01:45:36.069+0000] {taskinstance.py:1363} INFO - Starting attempt 1 of 2
[2022-10-28T01:45:36.069+0000] {taskinstance.py:1364} INFO - 
--------------------------------------------------------------------------------
[2022-10-28T01:45:36.195+0000] {taskinstance.py:1383} INFO - Executing <Task(PythonOperator): teste> on 2022-10-28 01:45:32.431312+00:00
[2022-10-28T01:45:36.203+0000] {standard_task_runner.py:55} INFO - Started process 14110 to run task
[2022-10-28T01:45:36.209+0000] {standard_task_runner.py:82} INFO - Running: ['airflow', 'tasks', 'run', 'carga_tb_carteira', 'teste', 'manual__2022-10-28T01:45:32.431312+00:00', '--job-id', '23', '--raw', '--subdir', 'DAGS_FOLDER/carga_tb_carteira.py', '--cfg-path', '/tmp/tmpsog4ge7i']
[2022-10-28T01:45:36.213+0000] {standard_task_runner.py:83} INFO - Job 23: Subtask teste
[2022-10-28T01:45:36.296+0000] {task_command.py:376} INFO - Running <TaskInstance: carga_tb_carteira.teste manual__2022-10-28T01:45:32.431312+00:00 [running]> on host cs-1097450612417-default
[2022-10-28T01:45:36.368+0000] {taskinstance.py:1590} INFO - Exporting the following env vars:
AIRFLOW_CTX_DAG_EMAIL=airflow@example.com
AIRFLOW_CTX_DAG_OWNER=Marcelo Henrique
AIRFLOW_CTX_DAG_ID=carga_tb_carteira
AIRFLOW_CTX_TASK_ID=teste
AIRFLOW_CTX_EXECUTION_DATE=2022-10-28T01:45:32.431312+00:00
AIRFLOW_CTX_TRY_NUMBER=1
AIRFLOW_CTX_DAG_RUN_ID=manual__2022-10-28T01:45:32.431312+00:00
[2022-10-28T01:45:36.370+0000] {taskinstance.py:1851} ERROR - Task failed with exception
Traceback (most recent call last):
  File "/home/marcelohenriqueleite35/carteira_ativos/env/lib/python3.9/site-packages/airflow/operators/python.py", line 175, in execute
    return_value = self.execute_callable()
  File "/home/marcelohenriqueleite35/carteira_ativos/env/lib/python3.9/site-packages/airflow/operators/python.py", line 193, in execute_callable
    return self.python_callable(*self.op_args, **self.op_kwargs)
  File "/home/marcelohenriqueleite35/carteira_ativos/jobs/create_datalake_01.py", line 13, in create_datalake
    Path(local + paths[path]).mkdir(exist_ok=True)
  File "/usr/lib/python3.9/pathlib.py", line 1312, in mkdir
    self._accessor.mkdir(self, mode)
FileNotFoundError: [Errno 2] No such file or directory: '/home/marcelohenriqueleite35/carteira_ativos/../../data/raw'
[2022-10-28T01:45:36.377+0000] {taskinstance.py:1401} INFO - Marking task as UP_FOR_RETRY. dag_id=carga_tb_carteira, task_id=teste, execution_date=20221028T014532, start_date=20221028T014536, end_date=20221028T014536
[2022-10-28T01:45:36.394+0000] {standard_task_runner.py:100} ERROR - Failed to execute job 23 for task teste ([Errno 2] No such file or directory: '/home/marcelohenriqueleite35/carteira_ativos/../../data/raw'; 14110)
[2022-10-28T01:45:36.421+0000] {local_task_job.py:164} INFO - Task exited with return code 1
[2022-10-28T01:45:36.436+0000] {local_task_job.py:273} INFO - 0 downstream tasks scheduled from follow-on schedule check
