[2022-10-28T01:40:43.261+0000] {taskinstance.py:1165} INFO - Dependencies all met for <TaskInstance: carga_tb_carteira.teste manual__2022-10-28T01:40:39.591254+00:00 [queued]>
[2022-10-28T01:40:43.278+0000] {taskinstance.py:1165} INFO - Dependencies all met for <TaskInstance: carga_tb_carteira.teste manual__2022-10-28T01:40:39.591254+00:00 [queued]>
[2022-10-28T01:40:43.278+0000] {taskinstance.py:1362} INFO - 
--------------------------------------------------------------------------------
[2022-10-28T01:40:43.278+0000] {taskinstance.py:1363} INFO - Starting attempt 1 of 2
[2022-10-28T01:40:43.279+0000] {taskinstance.py:1364} INFO - 
--------------------------------------------------------------------------------
[2022-10-28T01:40:43.455+0000] {taskinstance.py:1383} INFO - Executing <Task(PythonOperator): teste> on 2022-10-28 01:40:39.591254+00:00
[2022-10-28T01:40:43.466+0000] {standard_task_runner.py:55} INFO - Started process 13135 to run task
[2022-10-28T01:40:43.472+0000] {standard_task_runner.py:82} INFO - Running: ['airflow', 'tasks', 'run', 'carga_tb_carteira', 'teste', 'manual__2022-10-28T01:40:39.591254+00:00', '--job-id', '15', '--raw', '--subdir', 'DAGS_FOLDER/carga_tb_carteira.py', '--cfg-path', '/tmp/tmpftmrkqoy']
[2022-10-28T01:40:43.476+0000] {standard_task_runner.py:83} INFO - Job 15: Subtask teste
[2022-10-28T01:40:43.560+0000] {task_command.py:376} INFO - Running <TaskInstance: carga_tb_carteira.teste manual__2022-10-28T01:40:39.591254+00:00 [running]> on host cs-1097450612417-default
[2022-10-28T01:40:43.681+0000] {taskinstance.py:1590} INFO - Exporting the following env vars:
AIRFLOW_CTX_DAG_EMAIL=airflow@example.com
AIRFLOW_CTX_DAG_OWNER=Marcelo Henrique
AIRFLOW_CTX_DAG_ID=carga_tb_carteira
AIRFLOW_CTX_TASK_ID=teste
AIRFLOW_CTX_EXECUTION_DATE=2022-10-28T01:40:39.591254+00:00
AIRFLOW_CTX_TRY_NUMBER=1
AIRFLOW_CTX_DAG_RUN_ID=manual__2022-10-28T01:40:39.591254+00:00
[2022-10-28T01:40:43.690+0000] {taskinstance.py:1851} ERROR - Task failed with exception
Traceback (most recent call last):
  File "/home/marcelohenriqueleite35/carteira_ativos/env/lib/python3.9/site-packages/airflow/operators/python.py", line 175, in execute
    return_value = self.execute_callable()
  File "/home/marcelohenriqueleite35/carteira_ativos/env/lib/python3.9/site-packages/airflow/operators/python.py", line 193, in execute_callable
    return self.python_callable(*self.op_args, **self.op_kwargs)
  File "/home/marcelohenriqueleite35/carteira_ativos/jobs/create_datalake_01.py", line 12, in create_datalake
    Path(paths[path]).mkdir(exist_ok=True)
  File "/usr/lib/python3.9/pathlib.py", line 1312, in mkdir
    self._accessor.mkdir(self, mode)
FileNotFoundError: [Errno 2] No such file or directory: '../../data/raw'
[2022-10-28T01:40:43.706+0000] {taskinstance.py:1401} INFO - Marking task as UP_FOR_RETRY. dag_id=carga_tb_carteira, task_id=teste, execution_date=20221028T014039, start_date=20221028T014043, end_date=20221028T014043
[2022-10-28T01:40:43.727+0000] {standard_task_runner.py:100} ERROR - Failed to execute job 15 for task teste ([Errno 2] No such file or directory: '../../data/raw'; 13135)
[2022-10-28T01:40:43.764+0000] {local_task_job.py:164} INFO - Task exited with return code 1
[2022-10-28T01:40:43.788+0000] {local_task_job.py:273} INFO - 0 downstream tasks scheduled from follow-on schedule check
