[2022-10-28T01:45:07.140+0000] {taskinstance.py:1165} INFO - Dependencies all met for <TaskInstance: carga_tb_carteira.teste manual__2022-10-28T01:44:29.593898+00:00 [queued]>
[2022-10-28T01:45:07.151+0000] {taskinstance.py:1165} INFO - Dependencies all met for <TaskInstance: carga_tb_carteira.teste manual__2022-10-28T01:44:29.593898+00:00 [queued]>
[2022-10-28T01:45:07.152+0000] {taskinstance.py:1362} INFO - 
--------------------------------------------------------------------------------
[2022-10-28T01:45:07.153+0000] {taskinstance.py:1363} INFO - Starting attempt 2 of 2
[2022-10-28T01:45:07.153+0000] {taskinstance.py:1364} INFO - 
--------------------------------------------------------------------------------
[2022-10-28T01:45:07.300+0000] {taskinstance.py:1383} INFO - Executing <Task(PythonOperator): teste> on 2022-10-28 01:44:29.593898+00:00
[2022-10-28T01:45:07.305+0000] {standard_task_runner.py:55} INFO - Started process 14040 to run task
[2022-10-28T01:45:07.310+0000] {standard_task_runner.py:82} INFO - Running: ['airflow', 'tasks', 'run', 'carga_tb_carteira', 'teste', 'manual__2022-10-28T01:44:29.593898+00:00', '--job-id', '22', '--raw', '--subdir', 'DAGS_FOLDER/carga_tb_carteira.py', '--cfg-path', '/tmp/tmptym0ud07']
[2022-10-28T01:45:07.314+0000] {standard_task_runner.py:83} INFO - Job 22: Subtask teste
[2022-10-28T01:45:07.377+0000] {task_command.py:376} INFO - Running <TaskInstance: carga_tb_carteira.teste manual__2022-10-28T01:44:29.593898+00:00 [running]> on host cs-1097450612417-default
[2022-10-28T01:45:07.441+0000] {taskinstance.py:1590} INFO - Exporting the following env vars:
AIRFLOW_CTX_DAG_EMAIL=airflow@example.com
AIRFLOW_CTX_DAG_OWNER=Marcelo Henrique
AIRFLOW_CTX_DAG_ID=carga_tb_carteira
AIRFLOW_CTX_TASK_ID=teste
AIRFLOW_CTX_EXECUTION_DATE=2022-10-28T01:44:29.593898+00:00
AIRFLOW_CTX_TRY_NUMBER=2
AIRFLOW_CTX_DAG_RUN_ID=manual__2022-10-28T01:44:29.593898+00:00
[2022-10-28T01:45:07.444+0000] {taskinstance.py:1851} ERROR - Task failed with exception
Traceback (most recent call last):
  File "/home/marcelohenriqueleite35/carteira_ativos/env/lib/python3.9/site-packages/airflow/operators/python.py", line 175, in execute
    return_value = self.execute_callable()
  File "/home/marcelohenriqueleite35/carteira_ativos/env/lib/python3.9/site-packages/airflow/operators/python.py", line 193, in execute_callable
    return self.python_callable(*self.op_args, **self.op_kwargs)
  File "/home/marcelohenriqueleite35/carteira_ativos/jobs/create_datalake_01.py", line 11, in create_datalake
    local = Path().cwd() + '/'
TypeError: unsupported operand type(s) for +: 'PosixPath' and 'str'
[2022-10-28T01:45:07.448+0000] {taskinstance.py:1401} INFO - Marking task as FAILED. dag_id=carga_tb_carteira, task_id=teste, execution_date=20221028T014429, start_date=20221028T014507, end_date=20221028T014507
[2022-10-28T01:45:07.466+0000] {standard_task_runner.py:100} ERROR - Failed to execute job 22 for task teste (unsupported operand type(s) for +: 'PosixPath' and 'str'; 14040)
[2022-10-28T01:45:07.484+0000] {local_task_job.py:164} INFO - Task exited with return code 1
[2022-10-28T01:45:07.498+0000] {local_task_job.py:273} INFO - 0 downstream tasks scheduled from follow-on schedule check
